Workbook

Sheet Cover
B4: ELECTRICITY GRID TRANSMISSION
B5: THREE-WAY CORPORATE FINANCE MODEL
B7: Australian Energy Regulator (AER) | PTRM | REFM | Frontier | RAB | DTM
B12: Company | C12: GridCo Transmission Pty Ltd
B14: ABN | C14: 12 345 678 901
B16: Version | C16: v1.0 | AER DTM Integrated
B18: Date | C18: 05 April 2026
B20: Scope | C20: FY2019A-FY2023A Historical | FY2024E-FY2033E Forecast
B22: Reg Periods | C22: RCP1: FY2024-FY2028 | RCP2: FY2029-FY2033
B24: Jurisdiction | C24: Australia — AER Regulated Transmission
B26: Currency | C26: AUD Millions (unless stated)
B32: MODEL NAVIGATION
B34: Assumptions | C34: All inputs — the ONLY cells to change
B35: DTM | C35: AER Debt Term Model: 10yr trailing avg cost of debt
B36: REFM | C36: Revenue & Expenditure Forecasting Model (opex/capex)
B37: Frontier | C37: Frontier efficiency shift and X-factor
B38: RAB | C38: Regulatory Asset Base roll-forward
B39: PTRM | C39: Post Tax Revenue Model — Maximum Allowed Revenue (MAR)
B40: Income Statement | C40: 5yr historical + 10yr forecast P&L
B41: Balance Sheet | C41: 5yr historical + 10yr forecast Balance Sheet
B42: Cash Flow | C42: 5yr historical + 10yr forecast Cash Flow
B43: Checks | C43: Model integrity: BS, CFS & RAB checks

Sheet Assumptions
A1: ASSUMPTIONS — Electricity Grid Transmission Utility (AER Framework)
A2: $AUD Millions | B2: FY2019A | C2: FY2020A | D2: FY2021A | E2: FY2022A | F2: FY2023A | G2: FY2024E | H2: FY2025E | I2: FY2026E | J2: FY2027E | K2: FY2028E | L2: FY2029E | M2: FY2030E | N2: FY2031E | O2: FY2032E | P2: FY2033E
A4: WACC & Regulatory Parameters
A5: Post-Tax Nominal WACC (%) | B5: 0.065
A6: Risk-Free Rate (%) | B6: 0.043
A7: Equity Risk Premium (%) | B7: 0.062
A8: Asset Beta | B8: 0.45
A9: Gearing — Debt % of Capital | B9: 0.55
A10: Equity % of Capital | B10: =1-B9
A11: Gamma (AER Imputation Credits) | B11: 0.585
A12: Corporate Tax Rate (%) | B12: 0.3
A14: CPI Inflation (%)
A15: CPI Rate (%) | B15: 0.015 | C15: 0.017 | D15: 0.018 | E15: 0.03 | F15: 0.06 | G15: 0.025 | H15: 0.025 | I15: 0.025 | J15: 0.025 | K15: 0.025 | L15: 0.025 | M15: 0.025 | N15: 0.025 | O15: 0.025 | P15: 0.025
A17: Revenue & Volumes
A18: Transmission Volume (GWh) | B18: 48000 | C18: 49000 | D18: 50000 | E18: 51000 | F18: 52000 | G18: 52000 | H18: 53000 | I18: 54000 | J18: 55000 | K18: 56000 | L18: 57000 | M18: 58000 | N18: 59000 | O18: 60000 | P18: 61000
A19: Average Tariff ($/MWh) | B19: 12 | C19: 12.3 | D19: 12.7 | E19: 13 | F19: 13.2 | G19: 13.2 | H19: 13.5 | I19: 13.8 | J19: 14.1 | K19: 14.4 | L19: 14.7 | M19: 15 | N19: 15.3 | O19: 15.6 | P19: 15.9
A20: Connection & Access Fees ($M) | B20: 6 | C20: 6.5 | D20: 7 | E20: 7.5 | F20: 8 | G20: 8 | H20: 8.2 | I20: 8.4 | J20: 8.6 | K20: 8.8 | L20: 9 | M20: 9.2 | N20: 9.4 | O20: 9.6 | P20: 9.8
A22: Opex Forecast Allowances (Nominal $M)
A23: Network O&M | G23: 100 | H23: 102 | I23: 104 | J23: 106 | K23: 108 | L23: 110 | M23: 112 | N23: 114 | O23: 116 | P23: 118
A24: Corporate | G24: 58 | H24: 59 | I24: 60 | J24: 61 | K24: 62 | L24: 63 | M24: 64 | N24: 65 | O24: 66 | P24: 67
A25: Insurance | G25: 20 | H25: 20 | I25: 21 | J25: 21 | K25: 22 | L25: 22 | M25: 23 | N25: 23 | O25: 24 | P25: 24
A26: Regulatory | G26: 10 | H26: 10 | I26: 10 | J26: 10 | K26: 10 | L26: 11 | M26: 11 | N26: 11 | O26: 11 | P26: 11
A28: Capex Programme — Forecast (Nominal $M)
A29: Augmentation | G29: 200 | H29: 210 | I29: 220 | J29: 230 | K29: 240 | L29: 250 | M29: 260 | N29: 270 | O29: 280 | P29: 290
A30: Replacement | G30: 160 | H30: 165 | I30: 170 | J30: 175 | K30: 180 | L30: 185 | M30: 190 | N30: 195 | O30: 200 | P30: 205
A31: Connections | G31: 45 | H31: 47 | I31: 48 | J31: 50 | K31: 52 | L31: 54 | M31: 56 | N31: 58 | O31: 60 | P31: 62
A33: Regulatory Asset Base — Opening Balances
A34: Opening RAB — FY2019 ($M) | B34: 4800
A35: Standard Asset Life (years) | B35: 40
A36: Opening Accum. Regulatory Dep. ($M) | B36: 1200
A38: Accounting PP&E — Opening Balances (FY2019)
A39: Opening Gross PP&E ($M) | B39: 7800
A40: Opening Accum. D&A ($M) | B40: 2600
A41: Accounting Asset Life (years) | B41: 35
A43: Financing Parameters
A44: Opening LT Debt — FY2019 ($M) | B44: 3500
A45: Opening Cash — FY2019 ($M) | B45: 120
A46: Nominal Cost of Debt (%) | B46: 0.055
A47: Dividend Payout Ratio (%) | B47: 0.7
A48: Annual Debt Issuances ($M) | G48: 350 | H48: 360 | I48: 370 | J48: 380 | K48: 390 | L48: 400 | M48: 410 | N48: 420 | O48: 430 | P48: 440
...

Sheet DTM
A1: DEBT TERM MODEL (DTM) — AER 10-Year Trailing Average Cost of Debt
A2: % Rate | B2: FY2014A | C2: FY2015A | D2: FY2016A | E2: FY2017A | F2: FY2018A | G2: FY2019A | H2: FY2020A | I2: FY2021A | J2: FY2022A | K2: FY2023A | L2: FY2024E | M2: FY2025E | N2: FY2026E | O2: FY2027E | P2: FY2028E | Q2: FY2029E | R2: FY2030E | S2: FY2031E | T2: FY2032E | U2: FY2033E
A3: AER methodology: WACD = 10-year trailing average of benchmark bond yields (CGS + DRP + issuance costs). Each year 1/10th of total debt is re-priced at prevailing market rates.
A5: COMPONENT YIELDS BY VINTAGE YEAR
A6: Risk-Free Rate — 10yr CGS Yield (%) | B6: 0.035 | C6: 0.03 | D6: 0.025 | E6: 0.027 | F6: 0.029 | G6: 0.017 | H6: 0.009 | I6: 0.018 | J6: 0.037 | K6: 0.043 | L6: 0.04 | M6: 0.038 | N6: 0.037 | O6: 0.036 | P6: 0.036 | Q6: 0.036 | R6: 0.036 | S6: 0.036 | T6: 0.036 | U6: 0.036
A9: Debt Risk Premium — BBB+ Spread (%) | B9: 0.017 | C9: 0.018 | D9: 0.02 | E9: 0.019 | F9: 0.018 | G9: 0.02 | H9: 0.025 | I9: 0.022 | J9: 0.02 | K9: 0.019 | L9: 0.018 | M9: 0.0175 | N9: 0.017 | O9: 0.017 | P9: 0.017 | Q9: 0.017 | R9: 0.017 | S9: 0.017 | T9: 0.017 | U9: 0.017
A11: BENCHMARK YIELD CALCULATION
A12: Benchmark Yield (RFR + DRP, %) | B12: =B6+B9 | C12: =C6+C9 | D12: =D6+D9 | E12: =E6+E9 | F12: =F6+F9 | G12: =G6+G9 | H12: =H6+H9 | I12: =I6+I9 | ... U12: =U6+U9
A13: + Issuance Costs (%) | B13: 0.00125 | C13: 0.00125 | D13: 0.00125 | E13: 0.00125 | F13: 0.00125 | G13: 0.00125 | H13: 0.00125 | I13: 0.00125 | J13: 0.00125 | K13: 0.00125 | L13: 0.00125 | M13: 0.00125 | N13: 0.00125 | O13: 0.00125 | P13: 0.00125 | Q13: 0.00125 | R13: 0.00125 | S13: 0.00125 | T13: 0.00125 | U13: 0.00125
A14: Total Benchmark Cost of Debt (%) | B14: =B12+B13 | C14: =C12+C13 | D14: =D12+D13 | E14: =E12+E13 | F14: =F12+F13 | G14: =G12+G13 | H14: =H12+H13 | I14: =I12+I13 | ... U14: =U12+U13
A16: 10-YEAR TRAILING AVERAGE WACD
A17: Trailing Avg Cost of Debt (WACD, %) | B17: =AVERAGE(B14:B14) | C17: =AVERAGE(B14:C14) | D17: =AVERAGE(B14:D14) | E17: =AVERAGE(B14:E14) | F17: =AVERAGE(B14:F14) | G17: =AVERAGE(B14:G14) | H17: =AVERAGE(B14:H14) | I17: =AVERAGE(B14:I14) | J17: =AVERAGE(B14:J14) | K17: =AVERAGE(B14:K14) | L17: =AVERAGE(C14:L14) | M17: =AVERAGE(D14:M14) | N17: =AVERAGE(E14:N14) | O17: =AVERAGE(F14:O14) | P17: =AVERAGE(G14:P14) | Q17: =AVERAGE(H14:Q14) | R17: =AVERAGE(I14:R14) | ... U17: =AVERAGE(L14:U14)
A18: No. Vintage Years in Average | B18: 1 | C18: 2 | D18: 3 | E18: 4 | F18: 5 | G18: 6 | H18: 7 | I18: 8 | J18: 9 | K18: 10 | L18: 10 | M18: 10 | N18: 10 | O18: 10 | P18: 10 | Q18: 10 | R18: 10 | S18: 10 | T18: 10 | U18: 10
A20: WACD FEED TO FINANCIAL MODEL (FY2019A-FY2033E)
A21: Benchmark WACD for Model Year (%) | G21: =G17 | H21: =H17 | I21: =I17 | J21: =J17 | K21: =K17 | L21: =L17 | M21: =M17 | N21: =N17 | ... U21: =U17

Sheet Projects
A1: CAPITAL PROJECTS PIPELINE — Project-Level Capex Schedule
A2: $AUD Millions | B2: FY2019A | C2: FY2020A | D2: FY2021A | E2: FY2022A | F2: FY2023A | G2: FY2024E | H2: FY2025E | I2: FY2026E | J2: FY2027E | K2: FY2028E | L2: FY2029E | M2: FY2030E | N2: FY2031E | O2: FY2032E | P2: FY2033E
A4: Capital Projects ($M Nominal) — Forecast Period FY2024E–FY2033E
A5: Project Name | Type | Budget $M
A6: P001 Grid Modernisation Program | G6: 90 | H6: 130 | I6: 150 | J6: 120 | K6: 80 | L6: 60
A7: P002 Substation Upgrades — Zone A | G7: 70 | H7: 90 | I7: 50
A8: P003 HVDC Interconnect (Stage 1) | H8: 60 | I8: 120 | J8: 150 | K8: 120 | L8: 30
A9: P004 New Connection — Wind Farm A | G9: 25 | H9: 20
A10: P005 Transformer Replacement Program | G10: 35 | H10: 40 | I10: 45 | J10: 50 | K10: 55 | L10: 55 | M10: 50 | N10: 20
A11: P006 Protection Relay Upgrade | G11: 30 | H11: 35 | I11: 30 | J11: 25
A12: P007 New Connection — Solar Farm B | H12: 40 | I12: 40
A13: P008 Transmission Reconductoring | I13: 50 | J13: 70 | K13: 90 | L13: 90 | M13: 80 | N13: 40
A14: P009 Digital Twin Infrastructure | J14: 30 | K14: 35 | L14: 25
A15: P010 Reactive Power Support | K15: 25 | L15: 30 | M15: 20
A17: TOTAL CAPEX BY YEAR ($M) | B17: 280 | C17: 305 | D17: 330 | E17: 355 | F17: 380 | G17: =SUM(G6,G7,G8,G9,G10,G11,G12,G13,G14,G15) | H17: =SUM(H6,H7,H8,H9,H10,H11,H12,H13,H14,H15) | I17: =SUM(I6,I7,I8,I9,I10,I11,I12,I13,I14,I15) | J17: =SUM(J6,J7,J8,J9,J10,J11,J12,J13,J14,J15) | K17: =SUM(K6,K7,K8,K9,K10,K11,K12,K13,K14,K15) | L17: =SUM(L6,L7,L8,L9,L10,L11,L12,L13,L14,L15) | M17: =SUM(M6,M7,M8,M9,M10,M11,M12,M13,M14,M15) | N17: =SUM(N6,N7,N8,N9,N10,N11,N12,N13,N14,N15) | ... P17: =SUM(P6,P7,P8,P9,P10,P11,P12,P13,P14,P15)
A18: AUG=Augmentation (blue) | REPL=Replacement (yellow) | CONN=Connections (green)
A19: Augmentation (AUG) | B19: 150 | C19: 165 | D19: 175 | E19: 185 | F19: 195 | G19: 90 | H19: 190 | I19: 270 | J19: 300 | K19: 260 | L19: 145 | M19: 20 | N19: 0 | O19: 0 | P19: 0
A20: Replacement (REPL) | B20: 100 | C20: 105 | D20: 115 | E20: 130 | F20: 145 | G20: 135 | H20: 165 | I20: 175 | J20: 145 | K20: 145 | L20: 145 | M20: 130 | N20: 60 | O20: 0 | P20: 0
A21: Connections (CONN) | B21: 30 | C21: 35 | D21: 40 | E21: 40 | F21: 40 | G21: 25 | H21: 60 | I21: 40 | J21: 0 | K21: 0 | L21: 0 | M21: 0 | N21: 0 | O21: 0 | P21: 0

Sheet Capex
A1: CAPITAL EXPENDITURE SCHEDULE — Detailed Capex Build-Up
A2: $AUD Millions | B2: FY2019A | C2: FY2020A | D2: FY2021A | E2: FY2022A | F2: FY2023A | G2: FY2024E | H2: FY2025E | I2: FY2026E | J2: FY2027E | K2: FY2028E | L2: FY2029E | M2: FY2030E | N2: FY2031E | O2: FY2032E | P2: FY2033E
A4: Project-Sourced Capex by Category ($M Nominal)
A5: Augmentation Capex | B5: =Projects!B19 | C5: =Projects!C19 | D5: =Projects!D19 | E5: =Projects!E19 | F5: =Projects!F19 | G5: =Projects!G19 | H5: =Projects!H19 | I5: =Projects!I19 | ... P5: =Projects!P19
A6: Replacement / Renewal | B6: =Projects!B20 | C6: =Projects!C20 | D6: =Projects!D20 | E6: =Projects!E20 | F6: =Projects!F20 | G6: =Projects!G20 | H6: =Projects!H20 | I6: =Projects!I20 | ... P6: =Projects!P20
A7: Connections | B7: =Projects!B21 | C7: =Projects!C21 | D7: =Projects!D21 | E7: =Projects!E21 | F7: =Projects!F21 | G7: =Projects!G21 | H7: =Projects!H21 | I7: =Projects!I21 | ... P7: =Projects!P21
A8: Total Project Capex | B8: =B5+B6+B7 | C8: =C5+C6+C7 | D8: =D5+D6+D7 | E8: =E5+E6+E7 | F8: =F5+F6+F7 | G8: =G5+G6+G7 | H8: =H5+H6+H7 | I8: =I5+I6+I7 | ... P8: =P5+P6+P7
A10: Capitalised Overheads
A11: Overhead Capitalisation Rate (%) | B11: 0.08
A12: Capitalised Overheads ($M) | B12: =B8*$B$11 | C12: =C8*$B$11 | D12: =D8*$B$11 | E12: =E8*$B$11 | F12: =F8*$B$11 | G12: =G8*$B$11 | H12: =H8*$B$11 | I12: =I8*$B$11 | ... P12: =P8*$B$11
A13: TOTAL CAPEX (incl. overheads) | B13: =B8+B12 | C13: =C8+C12 | D13: =D8+D12 | E13: =E8+E12 | F13: =F8+F12 | G13: =G8+G12 | H13: =H8+H12 | I13: =I8+I12 | ... P13: =P8+P12
A15: Reconciliation to Assumptions Capex ($M)
A16: Assumptions Total (aug+repl+conn) | B16: 280 | C16: 305 | D16: 330 | E16: 355 | F16: 380 | G16: =Assumptions!G29+Assumptions!G30+Assumptions!G31 | H16: =Assumptions!H29+Assumptions!H30+Assumptions!H31 | I16: =Assumptions!I29+Assumptions!I30+Assumptions!I31 | J16: =Assumptions!J29+Assumptions!J30+Assumptions!J31 | K16: =Assumptions!K29+Assumptions!K30+Assumptions!K31 | L16: =Assumptions!L29+Assumptions!L30+Assumptions!L31 | M16: =Assumptions!M29+Assumptions!M30+Assumptions!M31 | N16: =Assumptions!N29+Assumptions!N30+Assumptions!N31 | ... P16: =Assumptions!P29+Assumptions!P30+Assumptions!P31
A17: Variance (Capex tab less Assumptions) | B17: 0 | C17: 0 | D17: 0 | E17: 0 | F17: 0 | G17: =G13-G16 | H17: =H13-H16 | I17: =I13-I16 | J17: =J13-J16 | K17: =K13-K16 | L17: =L13-L16 | M17: =M13-M16 | N17: =N13-N16 | ... P17: =P13-P16

Sheet Fixed Assets
A1: FIXED ASSET REGISTER — PP&E Roll-Forward by Asset Class
A2: $AUD Millions | B2: FY2019A | C2: FY2020A | D2: FY2021A | E2: FY2022A | F2: FY2023A | G2: FY2024E | H2: FY2025E | I2: FY2026E | J2: FY2027E | K2: FY2028E | L2: FY2029E | M2: FY2030E | N2: FY2031E | O2: FY2032E | P2: FY2033E
A4: Gross PP&E and Accumulated D&A by Asset Class ($M)
A5: TRANSMISSION LINES (Standard Life: 40 yrs)
A6: Opening Gross PP&E | B6: 3200 | C6: =B9 | D6: =C9 | E6: =D9 | F6: =E9 | G6: =F9 | H6: =G9 | I6: =H9 | J6: =I9 | ... P6: =O9
A7: + Additions (from Capex) | B7: ='Capex'!B13*0.5 | C7: ='Capex'!C13*0.5 | D7: ='Capex'!D13*0.5 | E7: ='Capex'!E13*0.5 | F7: ='Capex'!F13*0.5 | G7: ='Capex'!G13*0.5 | H7: ='Capex'!H13*0.5 | I7: ='Capex'!I13*0.5 | ... P7: ='Capex'!P13*0.5
A8: − Disposals | B8: 0 | C8: 0 | D8: 0 | E8: 0 | F8: 0 | G8: 0 | H8: 0 | I8: 0 | J8: 0 | K8: 0 | L8: 0 | M8: 0 | N8: 0 | O8: 0 | P8: 0
A9: Closing Gross PP&E | B9: =B6+B7-B8 | C9: =C6+C7-C8 | D9: =D6+D7-D8 | E9: =E6+E7-E8 | F9: =F6+F7-F8 | G9: =G6+G7-G8 | H9: =H6+H7-H8 | I9: =I6+I7-I8 | ... P9: =P6+P7-P8
A10: Opening Accum. D&A | B10: 1067 | C10: =B12 | D10: =C12 | E10: =D12 | F10: =E12 | G10: =F12 | H10: =G12 | I10: =H12 | J10: =I12 | ... P10: =O12
A11: D&A Charge (closing gross / life) | B11: =B9/40 | C11: =C9/40 | D11: =D9/40 | E11: =E9/40 | F11: =F9/40 | G11: =G9/40 | H11: =H9/40 | I11: =I9/40 | ... P11: =P9/40
A12: Closing Accum. D&A | B12: =B10+B11 | C12: =C10+C11 | D12: =D10+D11 | E12: =E10+E11 | F12: =F10+F11 | G12: =G10+G11 | H12: =H10+H11 | I12: =I10+I11 | ... P12: =P10+P11
A13: SUBSTATIONS (Standard Life: 40 yrs)
A14: Opening Gross PP&E | B14: 2400 | C14: =B17 | D14: =C17 | E14: =D17 | F14: =E17 | G14: =F17 | H14: =G17 | I14: =H17 | J14: =I17 | ... P14: =O17
A15: + Additions (from Capex) | B15: ='Capex'!B13*0.3 | C15: ='Capex'!C13*0.3 | D15: ='Capex'!D13*0.3 | E15: ='Capex'!E13*0.3 | F15: ='Capex'!F13*0.3 | G15: ='Capex'!G13*0.3 | H15: ='Capex'!H13*0.3 | I15: ='Capex'!I13*0.3 | ... P15: ='Capex'!P13*0.3
A16: − Disposals | B16: 0 | C16: 0 | D16: 0 | E16: 0 | F16: 0 | G16: 0 | H16: 0 | I16: 0 | J16: 0 | K16: 0 | L16: 0 | M16: 0 | N16: 0 | O16: 0 | P16: 0
A17: Closing Gross PP&E | B17: =B14+B15-B16 | C17: =C14+C15-C16 | D17: =D14+D15-D16 | E17: =E14+E15-E16 | F17: =F14+F15-F16 | G17: =G14+G15-G16 | H17: =H14+H15-H16 | I17: =I14+I15-I16 | ... P17: =P14+P15-P16
A18: Opening Accum. D&A | B18: 800 | C18: =B20 | D18: =C20 | E18: =D20 | F18: =E20 | G18: =F20 | H18: =G20 | I18: =H20 | J18: =I20 | ... P18: =O20
A19: D&A Charge (closing gross / life) | B19: =B17/40 | C19: =C17/40 | D19: =D17/40 | E19: =E17/40 | F19: =F17/40 | G19: =G17/40 | H19: =H17/40 | I19: =I17/40 | ... P19: =P17/40
A20: Closing Accum. D&A | B20: =B18+B19 | C20: =C18+C19 | D20: =D18+D19 | E20: =E18+E19 | F20: =F18+F19 | G20: =G18+G19 | H20: =H18+H19 | I20: =I18+I19 | ... P20: =P18+P19
A21: TRANSFORMERS (Standard Life: 30 yrs)
A22: Opening Gross PP&E | B22: 1200 | C22: =B25 | D22: =C25 | E22: =D25 | F22: =E25 | G22: =F25 | H22: =G25 | I22: =H25 | J22: =I25 | ... P22: =O25
A23: + Additions (from Capex) | B23: ='Capex'!B13*0.1 | C23: ='Capex'!C13*0.1 | D23: ='Capex'!D13*0.1 | E23: ='Capex'!E13*0.1 | F23: ='Capex'!F13*0.1 | G23: ='Capex'!G13*0.1 | H23: ='Capex'!H13*0.1 | I23: ='Capex'!I13*0.1 | ... P23: ='Capex'!P13*0.1
A24: − Disposals | B24: 0 | C24: 0 | D24: 0 | E24: 0 | F24: 0 | G24: 0 | H24: 0 | I24: 0 | J24: 0 | K24: 0 | L24: 0 | M24: 0 | N24: 0 | O24: 0 | P24: 0
A25: Closing Gross PP&E | B25: =B22+B23-B24 | C25: =C22+C23-C24 | D25: =D22+D23-D24 | E25: =E22+E23-E24 | F25: =F22+F23-F24 | G25: =G22+G23-G24 | H25: =H22+H23-H24 | I25: =I22+I23-I24 | ... P25: =P22+P23-P24
A26: Opening Accum. D&A | B26: 480 | C26: =B28 | D26: =C28 | E26: =D28 | F26: =E28 | G26: =F28 | H26: =G28 | I26: =H28 | J26: =I28 | ... P26: =O28
A27: D&A Charge (closing gross / life) | B27: =B25/30 | C27: =C25/30 | D27: =D25/30 | E27: =E25/30 | F27: =F25/30 | G27: =G25/30 | H27: =H25/30 | I27: =I25/30 | ... P27: =P25/30
A28: Closing Accum. D&A | B28: =B26+B27 | C28: =C26+C27 | D28: =D26+D27 | E28: =E26+E27 | F28: =F26+F27 | G28: =G26+G27 | H28: =H26+H27 | I28: =I26+I27 | ... P28: =P26+P27
A29: SCADA & CONTROL (Standard Life: 15 yrs)
A30: Opening Gross PP&E | B30: 600 | C30: =B33 | D30: =C33 | E30: =D33 | F30: =E33 | G30: =F33 | H30: =G33 | I30: =H33 | J30: =I33 | ... P30: =O33
A31: + Additions (from Capex) | B31: ='Capex'!B13*0.07 | C31: ='Capex'!C13*0.07 | D31: ='Capex'!D13*0.07 | E31: ='Capex'!E13*0.07 | F31: ='Capex'!F13*0.07 | G31: ='Capex'!G13*0.07 | H31: ='Capex'!H13*0.07 | I31: ='Capex'!I13*0.07 | ... P31: ='Capex'!P13*0.07
A32: − Disposals | B32: 0 | C32: 0 | D32: 0 | E32: 0 | F32: 0 | G32: 0 | H32: 0 | I32: 0 | J32: 0 | K32: 0 | L32: 0 | M32: 0 | N32: 0 | O32: 0 | P32: 0
A33: Closing Gross PP&E | B33: =B30+B31-B32 | C33: =C30+C31-C32 | D33: =D30+D31-D32 | E33: =E30+E31-E32 | F33: =F30+F31-F32 | G33: =G30+G31-G32 | H33: =H30+H31-H32 | I33: =I30+I31-I32 | ... P33: =P30+P31-P32
A34: Opening Accum. D&A | B34: 180 | C34: =B36 | D34: =C36 | E34: =D36 | F34: =E36 | G34: =F36 | H34: =G36 | I34: =H36 | J34: =I36 | ... P34: =O36
A35: D&A Charge (closing gross / life) | B35: =B33/15 | C35: =C33/15 | D35: =D33/15 | E35: =E33/15 | F35: =F33/15 | G35: =G33/15 | H35: =H33/15 | I35: =I33/15 | ... P35: =P33/15
A36: Closing Accum. D&A | B36: =B34+B35 | C36: =C34+C35 | D36: =D34+D35 | E36: =E34+E35 | F36: =F34+F35 | G36: =G34+G35 | H36: =H34+H35 | I36: =I34+I35 | ... P36: =P34+P35
A37: OTHER EQUIPMENT (Standard Life: 20 yrs)
A38: Opening Gross PP&E | B38: 400 | C38: =B41 | D38: =C41 | E38: =D41 | F38: =E41 | G38: =F41 | H38: =G41 | I38: =H41 | J38: =I41 | ... P38: =O41
A39: + Additions (from Capex) | B39: ='Capex'!B13*0.03 | C39: ='Capex'!C13*0.03 | D39: ='Capex'!D13*0.03 | E39: ='Capex'!E13*0.03 | F39: ='Capex'!F13*0.03 | G39: ='Capex'!G13*0.03 | H39: ='Capex'!H13*0.03 | I39: ='Capex'!I13*0.03 | ... P39: ='Capex'!P13*0.03
A40: − Disposals | B40: 0 | C40: 0 | D40: 0 | E40: 0 | F40: 0 | G40: 0 | H40: 0 | I40: 0 | J40: 0 | K40: 0 | L40: 0 | M40: 0 | N40: 0 | O40: 0 | P40: 0
A41: Closing Gross PP&E | B41: =B38+B39-B40 | C41: =C38+C39-C40 | D41: =D38+D39-D40 | E41: =E38+E39-E40 | F41: =F38+F39-F40 | G41: =G38+G39-G40 | H41: =H38+H39-H40 | I41: =I38+I39-I40 | ... P41: =P38+P39-P40
...

Sheet Workforce
A1: WORKFORCE — Headcount & Labour Cost Model
A2: $AUD Millions | B2: FY2019A | C2: FY2020A | D2: FY2021A | E2: FY2022A | F2: FY2023A | G2: FY2024E | H2: FY2025E | I2: FY2026E | J2: FY2027E | K2: FY2028E | L2: FY2029E | M2: FY2030E | N2: FY2031E | O2: FY2032E | P2: FY2033E
A4: On-Cost Parameters
A5: On-Cost Rate (super, leave, workers comp, etc.) | B5: 0.3
A7: Workforce by Department
A8: NETWORK OPERATIONS (field technicians & operators)
A9: Headcount (FTE) | B9: 248 | C9: 251 | D9: 254 | E9: 257 | F9: 260 | G9: 263 | H9: 267 | I9: 270 | J9: 273 | K9: 277 | L9: 280 | M9: 283 | N9: 287 | O9: 290 | P9: 294
A10: Avg. Salary ($/FTE, nominal $'000) | B10: 95 | C10: 97.4 | D10: 99.8 | E10: 102.3 | F10: 104.9 | G10: 107.5 | H10: =G10*(1+Assumptions!H15) | I10: =H10*(1+Assumptions!I15) | J10: =I10*(1+Assumptions!J15) | K10: =J10*(1+Assumptions!K15) | L10: =K10*(1+Assumptions!L15) | M10: =L10*(1+Assumptions!M15) | N10: =M10*(1+Assumptions!N15) | O10: =N10*(1+Assumptions!O15) | P10: =O10*(1+Assumptions!P15)
A11: Salary Cost ($M) | B11: =B9*B10/1000 | C11: =C9*C10/1000 | D11: =D9*D10/1000 | E11: =E9*E10/1000 | F11: =F9*F10/1000 | G11: =G9*G10/1000 | H11: =H9*H10/1000 | I11: =I9*I10/1000 | ... P11: =P9*P10/1000
A12: On-Costs ($M) | B12: =B11*$B$5 | C12: =C11*$B$5 | D12: =D11*$B$5 | E12: =E11*$B$5 | F12: =F11*$B$5 | G12: =G11*$B$5 | H12: =H11*$B$5 | I12: =I11*$B$5 | ... P12: =P11*$B$5
A13: Total Labour Cost ($M) | B13: =B11+B12 | C13: =C11+C12 | D13: =D11+D12 | E13: =E11+E12 | F13: =F11+F12 | G13: =G11+G12 | H13: =H11+H12 | I13: =I11+I12 | ... P13: =P11+P12
A15: ENGINEERING & PLANNING (asset, protection, planning)
A16: Headcount (FTE) | B16: 78 | C16: 79 | D16: 80 | E16: 81 | F16: 82 | G16: 83 | H16: 84 | I16: 86 | J16: 87 | K16: 89 | L16: 90 | M16: 92 | N16: 93 | O16: 95 | P16: 97
A17: Avg. Salary ($/FTE, nominal $'000) | B17: 120 | C17: 123 | D17: 126.1 | E17: 129.2 | F17: 132.5 | G17: 135.8 | H17: =G17*(1+Assumptions!H15) | I17: =H17*(1+Assumptions!I15) | J17: =I17*(1+Assumptions!J15) | K17: =J17*(1+Assumptions!K15) | L17: =K17*(1+Assumptions!L15) | M17: =L17*(1+Assumptions!M15) | N17: =M17*(1+Assumptions!N15) | O17: =N17*(1+Assumptions!O15) | P17: =O17*(1+Assumptions!P15)
A18: Salary Cost ($M) | B18: =B16*B17/1000 | C18: =C16*C17/1000 | D18: =D16*D17/1000 | E18: =E16*E17/1000 | F18: =F16*F17/1000 | G18: =G16*G17/1000 | H18: =H16*H17/1000 | I18: =I16*I17/1000 | ... P18: =P16*P17/1000
A19: On-Costs ($M) | B19: =B18*$B$5 | C19: =C18*$B$5 | D19: =D18*$B$5 | E19: =E18*$B$5 | F19: =F18*$B$5 | G19: =G18*$B$5 | H19: =H18*$B$5 | I19: =I18*$B$5 | ... P19: =P18*$B$5
A20: Total Labour Cost ($M) | B20: =B18+B19 | C20: =C18+C19 | D20: =D18+D19 | E20: =E18+E19 | F20: =F18+F19 | G20: =G18+G19 | H20: =H18+H19 | I20: =I18+I19 | ... P20: =P18+P19
A22: CORPORATE & SHARED SERVICES (finance, HR, legal, comms)
A23: Headcount (FTE) | B23: 118 | C23: 119 | D23: 120 | E23: 121 | F23: 122 | G23: 123 | H23: 124 | I23: 125 | J23: 126 | K23: 127 | L23: 128 | M23: 129 | N23: 130 | O23: 131 | P23: 132
A24: Avg. Salary ($/FTE, nominal $'000) | B24: 110 | C24: 112.7 | D24: 115.6 | E24: 118.5 | F24: 121.4 | G24: 124.5 | H24: =G24*(1+Assumptions!H15) | I24: =H24*(1+Assumptions!I15) | J24: =I24*(1+Assumptions!J15) | K24: =J24*(1+Assumptions!K15) | L24: =K24*(1+Assumptions!L15) | M24: =L24*(1+Assumptions!M15) | N24: =M24*(1+Assumptions!N15) | O24: =N24*(1+Assumptions!O15) | P24: =O24*(1+Assumptions!P15)
A25: Salary Cost ($M) | B25: =B23*B24/1000 | C25: =C23*C24/1000 | D25: =D23*D24/1000 | E25: =E23*E24/1000 | F25: =F23*F24/1000 | G25: =G23*G24/1000 | H25: =H23*H24/1000 | I25: =I23*I24/1000 | ... P25: =P23*P24/1000
A26: On-Costs ($M) | B26: =B25*$B$5 | C26: =C25*$B$5 | D26: =D25*$B$5 | E26: =E25*$B$5 | F26: =F25*$B$5 | G26: =G25*$B$5 | H26: =H25*$B$5 | I26: =I25*$B$5 | ... P26: =P25*$B$5
A27: Total Labour Cost ($M) | B27: =B25+B26 | C27: =C25+C26 | D27: =D25+D26 | E27: =E25+E26 | F27: =F25+F26 | G27: =G25+G26 | H27: =H25+H26 | I27: =I25+I26 | ... P27: =P25+P26
A29: ICT & DIGITAL (infrastructure, cybersecurity, data)
A30: Headcount (FTE) | B30: 42 | C30: 43 | D30: 44 | E30: 45 | F30: 46 | G30: 48 | H30: 50 | I30: 52 | J30: 54 | K30: 55 | L30: 57 | M30: 58 | N30: 59 | O30: 60 | P30: 61
A31: Avg. Salary ($/FTE, nominal $'000) | B31: 115 | C31: 117.9 | D31: 120.8 | E31: 123.8 | F31: 126.9 | G31: 130.1 | H31: =G31*(1+Assumptions!H15) | I31: =H31*(1+Assumptions!I15) | J31: =I31*(1+Assumptions!J15) | K31: =J31*(1+Assumptions!K15) | L31: =K31*(1+Assumptions!L15) | M31: =L31*(1+Assumptions!M15) | N31: =M31*(1+Assumptions!N15) | O31: =N31*(1+Assumptions!O15) | P31: =O31*(1+Assumptions!P15)
A32: Salary Cost ($M) | B32: =B30*B31/1000 | C32: =C30*C31/1000 | D32: =D30*D31/1000 | E32: =E30*E31/1000 | F32: =F30*F31/1000 | G32: =G30*G31/1000 | H32: =H30*H31/1000 | I32: =I30*I31/1000 | ... P32: =P30*P31/1000
A33: On-Costs ($M) | B33: =B32*$B$5 | C33: =C32*$B$5 | D33: =D32*$B$5 | E33: =E32*$B$5 | F33: =F32*$B$5 | G33: =G32*$B$5 | H33: =H32*$B$5 | I33: =I32*$B$5 | ... P33: =P32*$B$5
A34: Total Labour Cost ($M) | B34: =B32+B33 | C34: =C32+C33 | D34: =D32+D33 | E34: =E32+E33 | F34: =F32+F33 | G34: =G32+G33 | H34: =H32+H33 | I34: =I32+I33 | ... P34: =P32+P33
A36: EXECUTIVE & MANAGEMENT (C-suite, directors, managers)
A37: Headcount (FTE) | B37: 25 | C37: 25 | D37: 25 | E37: 25 | F37: 25 | G37: 25 | H37: 25 | I37: 25 | J37: 25 | K37: 25 | L37: 25 | M37: 25 | N37: 26 | O37: 26 | P37: 26
A38: Avg. Salary ($/FTE, nominal $'000) | B38: 250 | C38: 256.2 | D38: 262.7 | E38: 269.2 | F38: 276 | G38: 282.9 | H38: =G38*(1+Assumptions!H15) | I38: =H38*(1+Assumptions!I15) | J38: =I38*(1+Assumptions!J15) | K38: =J38*(1+Assumptions!K15) | L38: =K38*(1+Assumptions!L15) | M38: =L38*(1+Assumptions!M15) | N38: =M38*(1+Assumptions!N15) | O38: =N38*(1+Assumptions!O15) | P38: =O38*(1+Assumptions!P15)
A39: Salary Cost ($M) | B39: =B37*B38/1000 | C39: =C37*C38/1000 | D39: =D37*D38/1000 | E39: =E37*E38/1000 | F39: =F37*F38/1000 | G39: =G37*G38/1000 | H39: =H37*H38/1000 | I39: =I37*I38/1000 | ... P39: =P37*P38/1000
A40: On-Costs ($M) | B40: =B39*$B$5 | C40: =C39*$B$5 | D40: =D39*$B$5 | E40: =E39*$B$5 | F40: =F39*$B$5 | G40: =G39*$B$5 | H40: =H39*$B$5 | I40: =I39*$B$5 | ... P40: =P39*$B$5
A41: Total Labour Cost ($M) | B41: =B39+B40 | C41: =C39+C40 | D41: =D39+D40 | E41: =E39+E40 | F41: =F39+F40 | G41: =G39+G40 | H41: =H39+H40 | I41: =I39+I40 | ... P41: =P39+P40
A44: TOTAL WORKFORCE SUMMARY
A45: Total Headcount (FTE) | B45: =B9+B16+B23+B30+B37 | C45: =C9+C16+C23+C30+C37 | D45: =D9+D16+D23+D30+D37 | E45: =E9+E16+E23+E30+E37 | F45: =F9+F16+F23+F30+F37 | G45: =G9+G16+G23+G30+G37 | H45: =H9+H16+H23+H30+H37 | I45: =I9+I16+I23+I30+I37 | ... P45: =P9+P16+P23+P30+P37
A46: Total Labour Cost ($M) | B46: =B13+B20+B27+B34+B41 | C46: =C13+C20+C27+C34+C41 | D46: =D13+D20+D27+D34+D41 | E46: =E13+E20+E27+E34+E41 | F46: =F13+F20+F27+F34+F41 | G46: =G13+G20+G27+G34+G41 | H46: =H13+H20+H27+H34+H41 | I46: =I13+I20+I27+I34+I41 | ... P46: =P13+P20+P27+P34+P41
A47: → Network Ops Cost (feeds O&M line) | B47: =B13 | C47: =C13 | D47: =D13 | E47: =E13 | F47: =F13 | G47: =G13 | H47: =H13 | I47: =I13 | ... P47: =P13
A48: → Support Functions Cost (feeds Corporate line) | B48: =B20+B27+B34+B41 | C48: =C20+C27+C34+C41 | D48: =D20+D27+D34+D41 | E48: =E20+E27+E34+E41 | F48: =F20+F27+F34+F41 | G48: =G20+G27+G34+G41 | H48: =H20+H27+H34+H41 | I48: =I20+I27+I34+I41 | ... P48: =P20+P27+P34+P41

Sheet Maintenance
A1: MAINTENANCE — Asset Maintenance Cost Schedule
A2: $AUD Millions | B2: FY2019A | C2: FY2020A | D2: FY2021A | E2: FY2022A | F2: FY2023A | G2: FY2024E | H2: FY2025E | I2: FY2026E | J2: FY2027E | K2: FY2028E | L2: FY2029E | M2: FY2030E | N2: FY2031E | O2: FY2032E | P2: FY2033E
A4: PLANNED / PREVENTIVE MAINTENANCE ($M)
A5: Transmission Lines | B5: 24 | C5: 24.4 | D5: 24.8 | E5: 25.6 | F5: 27.1 | G5: =27.1*(1+Assumptions!G15) | H5: =G5*(1+Assumptions!H15) | I5: =H5*(1+Assumptions!I15) | J5: =I5*(1+Assumptions!J15) | K5: =J5*(1+Assumptions!K15) | L5: =K5*(1+Assumptions!L15) | M5: =L5*(1+Assumptions!M15) | N5: =M5*(1+Assumptions!N15) | O5: =N5*(1+Assumptions!O15) | P5: =O5*(1+Assumptions!P15)
A6: Substations | B6: 18 | C6: 18.3 | D6: 18.6 | E6: 19.2 | F6: 20.3 | G6: =20.3*(1+Assumptions!G15) | H6: =G6*(1+Assumptions!H15) | I6: =H6*(1+Assumptions!I15) | J6: =I6*(1+Assumptions!J15) | K6: =J6*(1+Assumptions!K15) | L6: =K6*(1+Assumptions!L15) | M6: =L6*(1+Assumptions!M15) | N6: =M6*(1+Assumptions!N15) | O6: =N6*(1+Assumptions!O15) | P6: =O6*(1+Assumptions!P15)
A7: Transformers | B7: 12 | C7: 12.2 | D7: 12.4 | E7: 12.8 | F7: 13.5 | G7: =13.5*(1+Assumptions!G15) | H7: =G7*(1+Assumptions!H15) | I7: =H7*(1+Assumptions!I15) | J7: =I7*(1+Assumptions!J15) | K7: =J7*(1+Assumptions!K15) | L7: =K7*(1+Assumptions!L15) | M7: =L7*(1+Assumptions!M15) | N7: =M7*(1+Assumptions!N15) | O7: =N7*(1+Assumptions!O15) | P7: =O7*(1+Assumptions!P15)
A8: SCADA & Control | B8: 8 | C8: 8.1 | D8: 8.3 | E8: 8.5 | F8: 9 | G8: =9.0*(1+Assumptions!G15) | H8: =G8*(1+Assumptions!H15) | I8: =H8*(1+Assumptions!I15) | J8: =I8*(1+Assumptions!J15) | K8: =J8*(1+Assumptions!K15) | L8: =K8*(1+Assumptions!L15) | M8: =L8*(1+Assumptions!M15) | N8: =M8*(1+Assumptions!N15) | O8: =N8*(1+Assumptions!O15) | P8: =O8*(1+Assumptions!P15)
A9: Other Equipment | B9: 4.5 | C9: 4.6 | D9: 4.7 | E9: 4.8 | F9: 5.1 | G9: =5.1*(1+Assumptions!G15) | H9: =G9*(1+Assumptions!H15) | I9: =H9*(1+Assumptions!I15) | J9: =I9*(1+Assumptions!J15) | K9: =J9*(1+Assumptions!K15) | L9: =K9*(1+Assumptions!L15) | M9: =L9*(1+Assumptions!M15) | N9: =M9*(1+Assumptions!N15) | O9: =N9*(1+Assumptions!O15) | P9: =O9*(1+Assumptions!P15)
A10: Total Planned Maintenance | B10: =B5+B6+B7+B8+B9 | C10: =C5+C6+C7+C8+C9 | D10: =D5+D6+D7+D8+D9 | E10: =E5+E6+E7+E8+E9 | F10: =F5+F6+F7+F8+F9 | G10: =G5+G6+G7+G8+G9 | H10: =H5+H6+H7+H8+H9 | I10: =I5+I6+I7+I8+I9 | ... P10: =P5+P6+P7+P8+P9
A12: CORRECTIVE / EMERGENCY MAINTENANCE ($M)
A13: Corrective Rate (% of planned) | B13: 0.15
A14: Total Corrective Maintenance | B14: =B10*$B$13 | C14: =C10*$B$13 | D14: =D10*$B$13 | E14: =E10*$B$13 | F14: =F10*$B$13 | G14: =G10*$B$13 | H14: =H10*$B$13 | I14: =I10*$B$13 | ... P14: =P10*$B$13
A16: TOTAL MAINTENANCE COST ($M) — Feeds Network O&M in IS
A17: Total Maintenance (Planned + Corrective) | B17: =B10+B14 | C17: =C10+C14 | D17: =D10+D14 | E17: =E10+E14 | F17: =F10+F14 | G17: =G10+G14 | H17: =H10+H14 | I17: =I10+I14 | ... P17: =P10+P14
A18: Note: Maintenance total is a supporting schedule. IS Network O&M is currently driven by Assumptions/REFM. Update REFM O&M inputs to align with this schedule.

Sheet REFM
A1: REVENUE & EXPENDITURE FORECASTING MODEL (REFM)
A2: $AUD Millions | B2: FY2019A | C2: FY2020A | D2: FY2021A | E2: FY2022A | F2: FY2023A | G2: FY2024E | H2: FY2025E | I2: FY2026E | J2: FY2027E | K2: FY2028E | L2: FY2029E | M2: FY2030E | N2: FY2031E | O2: FY2032E | P2: FY2033E
A4: Operating Expenditure ($M)
A5: Network O&M | B5: =Assumptions!B61 | C5: =Assumptions!C61 | D5: =Assumptions!D61 | E5: =Assumptions!E61 | F5: =Assumptions!F61 | G5: =Assumptions!G23 | H5: =Assumptions!H23 | I5: =Assumptions!I23 | J5: =Assumptions!J23 | K5: =Assumptions!K23 | L5: =Assumptions!L23 | M5: =Assumptions!M23 | N5: =Assumptions!N23 | ... P5: =Assumptions!P23
A6: Corporate | B6: =Assumptions!B62 | C6: =Assumptions!C62 | D6: =Assumptions!D62 | E6: =Assumptions!E62 | F6: =Assumptions!F62 | G6: =Assumptions!G24 | H6: =Assumptions!H24 | I6: =Assumptions!I24 | J6: =Assumptions!J24 | K6: =Assumptions!K24 | L6: =Assumptions!L24 | M6: =Assumptions!M24 | N6: =Assumptions!N24 | ... P6: =Assumptions!P24
A7: Insurance | B7: =Assumptions!B63 | C7: =Assumptions!C63 | D7: =Assumptions!D63 | E7: =Assumptions!E63 | F7: =Assumptions!F63 | G7: =Assumptions!G25 | H7: =Assumptions!H25 | I7: =Assumptions!I25 | J7: =Assumptions!J25 | K7: =Assumptions!K25 | L7: =Assumptions!L25 | M7: =Assumptions!M25 | N7: =Assumptions!N25 | ... P7: =Assumptions!P25
A8: Regulatory | B8: =Assumptions!B64 | C8: =Assumptions!C64 | D8: =Assumptions!D64 | E8: =Assumptions!E64 | F8: =Assumptions!F64 | G8: =Assumptions!G26 | H8: =Assumptions!H26 | I8: =Assumptions!I26 | J8: =Assumptions!J26 | K8: =Assumptions!K26 | L8: =Assumptions!L26 | M8: =Assumptions!M26 | N8: =Assumptions!N26 | ... P8: =Assumptions!P26
A9: Total Opex | B9: =SUM(B5:B8) | C9: =SUM(C5:C8) | D9: =SUM(D5:D8) | E9: =SUM(E5:E8) | F9: =SUM(F5:F8) | G9: =SUM(G5:G8) | H9: =SUM(H5:H8) | I9: =SUM(I5:I8) | ... P9: =SUM(P5:P8)
A11: Capital Expenditure ($M) — Forecast sourced from Capex tab
A12: Augmentation Capex | B12: =Assumptions!B67 | C12: =Assumptions!C67 | D12: =Assumptions!D67 | E12: =Assumptions!E67 | F12: =Assumptions!F67 | G12: =Capex!G5 | H12: =Capex!H5 | I12: =Capex!I5 | J12: =Capex!J5 | K12: =Capex!K5 | L12: =Capex!L5 | M12: =Capex!M5 | N12: =Capex!N5 | ... P12: =Capex!P5
A13: Replacement / Renewal | B13: =Assumptions!B68 | C13: =Assumptions!C68 | D13: =Assumptions!D68 | E13: =Assumptions!E68 | F13: =Assumptions!F68 | G13: =Capex!G6 | H13: =Capex!H6 | I13: =Capex!I6 | J13: =Capex!J6 | K13: =Capex!K6 | L13: =Capex!L6 | M13: =Capex!M6 | N13: =Capex!N6 | ... P13: =Capex!P6
A14: Connections | B14: =Assumptions!B69 | C14: =Assumptions!C69 | D14: =Assumptions!D69 | E14: =Assumptions!E69 | F14: =Assumptions!F69 | G14: =Capex!G7 | H14: =Capex!H7 | I14: =Capex!I7 | J14: =Capex!J7 | K14: =Capex!K7 | L14: =Capex!L7 | M14: =Capex!M7 | N14: =Capex!N7 | ... P14: =Capex!P7
A15: Total Capex | B15: =SUM(B12:B14) | C15: =SUM(C12:C14) | D15: =SUM(D12:D14) | E15: =SUM(E12:E14) | F15: =SUM(F12:F14) | G15: =SUM(G12:G14) | H15: =SUM(H12:H14) | I15: =SUM(I12:I14) | ... P15: =SUM(P12:P14)
A17: Opex Variance — Allowed vs Actual ($M)
A18: Opex Allowed (from PTRM) | B18: =PTRM!B7 | C18: =PTRM!C7 | D18: =PTRM!D7 | E18: =PTRM!E7 | F18: =PTRM!F7 | G18: =PTRM!G7 | H18: =PTRM!H7 | I18: =PTRM!I7 | ... P18: =PTRM!P7
A19: Opex Actual (this sheet) | B19: =B9 | C19: =C9 | D19: =D9 | E19: =E9 | F19: =F9 | G19: =G9 | H19: =H9 | I19: =I9 | ... P19: =P9
A20: Variance (Allowed − Actual) | B20: =B18-B19 | C20: =C18-C19 | D20: =D18-D19 | E20: =E18-E19 | F20: =F18-F19 | G20: =G18-G19 | H20: =H18-H19 | I20: =I18-I19 | ... P20: =P18-P19
A22: Efficiency Carryover Mechanism (ECM)
A23: ECM Sharing Rate | B23: 0.3
A24: ECM Benefit ($M) | B24: =MAX(B20,0)*$B$23 | C24: =MAX(C20,0)*$B$23 | D24: =MAX(D20,0)*$B$23 | E24: =MAX(E20,0)*$B$23 | F24: =MAX(F20,0)*$B$23 | G24: =MAX(G20,0)*$B$23 | H24: =MAX(H20,0)*$B$23 | I24: =MAX(I20,0)*$B$23 | ... P24: =MAX(P20,0)*$B$23

Sheet Frontier
A1: FRONTIER PRICING MODEL — Efficiency Shift & X-Factor
A2: $AUD Millions | B2: FY2019A | C2: FY2020A | D2: FY2021A | E2: FY2022A | F2: FY2023A | G2: FY2024E | H2: FY2025E | I2: FY2026E | J2: FY2027E | K2: FY2028E | L2: FY2029E | M2: FY2030E | N2: FY2031E | O2: FY2032E | P2: FY2033E
A4: Frontier Efficiency Adjustment
A5: Cumulative Frontier Shift Factor | B5: 1 | C5: 1 | D5: 1 | E5: 1 | F5: 1 | G5: =(1-Assumptions!$B$56)^1 | H5: =(1-Assumptions!$B$56)^2 | I5: =(1-Assumptions!$B$56)^3 | J5: =(1-Assumptions!$B$56)^4 | K5: =(1-Assumptions!$B$56)^5 | L5: =(1-Assumptions!$B$56)^6 | M5: =(1-Assumptions!$B$56)^7 | N5: =(1-Assumptions!$B$56)^8 | O5: =(1-Assumptions!$B$56)^9 | P5: =(1-Assumptions!$B$56)^10
A6: Raw Opex — from REFM ($M) | B6: =REFM!B9 | C6: =REFM!C9 | D6: =REFM!D9 | E6: =REFM!E9 | F6: =REFM!F9 | G6: =REFM!G9 | H6: =REFM!H9 | I6: =REFM!I9 | ... P6: =REFM!P9
A7: Frontier-Adjusted Opex Allowance ($M) | B7: =REFM!B9 | C7: =REFM!C9 | D7: =REFM!D9 | E7: =REFM!E9 | F7: =REFM!F9 | G7: =REFM!G9*G5*Assumptions!$B$57 | H7: =REFM!H9*H5*Assumptions!$B$57 | I7: =REFM!I9*I5*Assumptions!$B$57 | J7: =REFM!J9*J5*Assumptions!$B$57 | K7: =REFM!K9*K5*Assumptions!$B$57 | L7: =REFM!L9*L5*Assumptions!$B$57 | M7: =REFM!M9*M5*Assumptions!$B$57 | N7: =REFM!N9*N5*Assumptions!$B$57 | ... P7: =REFM!P9*P5*Assumptions!$B$57
A8: Raw Capex — from REFM ($M) | B8: =REFM!B15 | C8: =REFM!C15 | D8: =REFM!D15 | E8: =REFM!E15 | F8: =REFM!F15 | G8: =REFM!G15 | H8: =REFM!H15 | I8: =REFM!I15 | ... P8: =REFM!P15
A9: Frontier-Adjusted Capex ($M) | B9: =REFM!B15 | C9: =REFM!C15 | D9: =REFM!D15 | E9: =REFM!E15 | F9: =REFM!F15 | G9: =REFM!G15*Assumptions!$B$58 | H9: =REFM!H15*Assumptions!$B$58 | I9: =REFM!I15*Assumptions!$B$58 | J9: =REFM!J15*Assumptions!$B$58 | K9: =REFM!K15*Assumptions!$B$58 | L9: =REFM!L15*Assumptions!$B$58 | M9: =REFM!M15*Assumptions!$B$58 | N9: =REFM!N15*Assumptions!$B$58 | ... P9: =REFM!P15*Assumptions!$B$58
A11: X-Factor (%) | B11: 0 | C11: 0 | D11: 0 | E11: 0 | F11: 0 | G11: =Assumptions!$B$56 | H11: =Assumptions!$B$56 | I11: =Assumptions!$B$56 | J11: =Assumptions!$B$56 | K11: =Assumptions!$B$56 | L11: =Assumptions!$B$56 | M11: =Assumptions!$B$56 | N11: =Assumptions!$B$56 | ... P11: =Assumptions!$B$56

Sheet RAB
A1: REGULATORY ASSET BASE (RAB) ROLL-FORWARD
A2: $AUD Millions | B2: FY2019A | C2: FY2020A | D2: FY2021A | E2: FY2022A | F2: FY2023A | G2: FY2024E | H2: FY2025E | I2: FY2026E | J2: FY2027E | K2: FY2028E | L2: FY2029E | M2: FY2030E | N2: FY2031E | O2: FY2032E | P2: FY2033E
A4: RAB Roll-Forward ($M)
A5: Opening RAB | B5: =Assumptions!$B$34 | C5: =B9 | D5: =C9 | E5: =D9 | F5: =E9 | G5: =F9 | H5: =G9 | I5: =H9 | J5: =I9 | ... P5: =O9
A6: + CPI Indexation | B6: =B5*Assumptions!B15 | C6: =C5*Assumptions!C15 | D6: =D5*Assumptions!D15 | E6: =E5*Assumptions!E15 | F6: =F5*Assumptions!F15 | G6: =G5*Assumptions!G15 | H6: =H5*Assumptions!H15 | I6: =I5*Assumptions!I15 | ... P6: =P5*Assumptions!P15
A7: + Capex Additions | B7: =REFM!B15 | C7: =REFM!C15 | D7: =REFM!D15 | E7: =REFM!E15 | F7: =REFM!F15 | G7: =REFM!G15 | H7: =REFM!H15 | I7: =REFM!I15 | ... P7: =REFM!P15
A8: − Regulatory Depreciation | B8: =B5/Assumptions!$B$35 | C8: =C5/Assumptions!$B$35 | D8: =D5/Assumptions!$B$35 | E8: =E5/Assumptions!$B$35 | F8: =F5/Assumptions!$B$35 | G8: =G5/Assumptions!$B$35 | H8: =H5/Assumptions!$B$35 | I8: =I5/Assumptions!$B$35 | ... P8: =P5/Assumptions!$B$35
A9: = Closing RAB | B9: =B5+B6+B7-B8 | C9: =C5+C6+C7-C8 | D9: =D5+D6+D7-D8 | E9: =E5+E6+E7-E8 | F9: =F5+F6+F7-F8 | G9: =G5+G6+G7-G8 | H9: =H5+H6+H7-H8 | I9: =I5+I6+I7-I8 | ... P9: =P5+P6+P7-P8
A11: Average RAB (Return on RAB base) | B11: =(B5+B9)/2 | C11: =(C5+C9)/2 | D11: =(D5+D9)/2 | E11: =(E5+E9)/2 | F11: =(F5+F9)/2 | G11: =(G5+G9)/2 | H11: =(H5+H9)/2 | I11: =(I5+I9)/2 | ... P11: =(P5+P9)/2
A13: Accumulated Regulatory Depreciation ($M)
A14: Accum. Reg. Depreciation (closing) | B14: =Assumptions!$B$36+B8 | C14: =B14+C8 | D14: =C14+D8 | E14: =D14+E8 | F14: =E14+F8 | G14: =F14+G8 | H14: =G14+H8 | I14: =H14+I8 | J14: =I14+J8 | ... P14: =O14+P8

Sheet PTRM
A1: POST TAX REVENUE MODEL (PTRM) — Maximum Allowed Revenue
A2: $AUD Millions | B2: FY2019A | C2: FY2020A | D2: FY2021A | E2: FY2022A | F2: FY2023A | G2: FY2024E | H2: FY2025E | I2: FY2026E | J2: FY2027E | K2: FY2028E | L2: FY2029E | M2: FY2030E | N2: FY2031E | O2: FY2032E | P2: FY2033E
A4: MAR Build-Up ($M)
A5: Return on RAB (Avg RAB × WACC) | B5: 319.5 | C5: 335.7 | D5: 353.8 | E5: 375.8 | F5: 407.4 | G5: =RAB!G11*Assumptions!$B$5 | H5: =RAB!H11*Assumptions!$B$5 | I5: =RAB!I11*Assumptions!$B$5 | J5: =RAB!J11*Assumptions!$B$5 | K5: =RAB!K11*Assumptions!$B$5 | L5: =RAB!L11*Assumptions!$B$5 | M5: =RAB!M11*Assumptions!$B$5 | N5: =RAB!N11*Assumptions!$B$5 | ... P5: =RAB!P11*Assumptions!$B$5
A6: Return of RAB (Regulatory Depreciation) | B6: 120 | C6: 125.8 | D6: 132.4 | E6: 139.7 | F6: 149.3 | G6: =RAB!G8 | H6: =RAB!H8 | I6: =RAB!I8 | J6: =RAB!J8 | K6: =RAB!K8 | L6: =RAB!L8 | M6: =RAB!M8 | N6: =RAB!N8 | ... P6: =RAB!P8
A7: Opex Allowance (Frontier-adjusted) | B7: 168 | C7: 172 | D7: 176 | E7: 181 | F7: 185 | G7: =Frontier!G7 | H7: =Frontier!H7 | I7: =Frontier!I7 | J7: =Frontier!J7 | K7: =Frontier!K7 | L7: =Frontier!L7 | M7: =Frontier!M7 | N7: =Frontier!N7 | ... P7: =Frontier!P7
A8: Tax Allowance | B8: 39.7 | C8: 41.8 | D8: 44 | E8: 46.7 | F8: 50.7 | G8: =G15 | H8: =H15 | I8: =I15 | J8: =J15 | K8: =K15 | L8: =L15 | M8: =M15 | N8: =N15 | ... P8: =P15
A9: Maximum Allowed Revenue (MAR) | B9: 603 | C9: 629 | D9: 666 | E9: 687 | F9: 731 | G9: =G5+G6+G7+G8 | H9: =H5+H6+H7+H8 | I9: =I5+I6+I7+I8 | J9: =J5+J6+J7+J8 | K9: =K5+K6+K7+K8 | L9: =L5+L6+L7+L8 | M9: =M5+M6+M7+M8 | N9: =N5+N6+N7+N8 | ... P9: =P5+P6+P7+P8
A11: Tax Allowance Build-Up ($M)
A12: Taxable Income (Return on RAB) | B12: 319.5 | C12: 335.7 | D12: 353.8 | E12: 375.8 | F12: 407.4 | G12: =RAB!G11*Assumptions!$B$5 | H12: =RAB!H11*Assumptions!$B$5 | I12: =RAB!I11*Assumptions!$B$5 | J12: =RAB!J11*Assumptions!$B$5 | K12: =RAB!K11*Assumptions!$B$5 | L12: =RAB!L11*Assumptions!$B$5 | M12: =RAB!M11*Assumptions!$B$5 | N12: =RAB!N11*Assumptions!$B$5 | ... P12: =RAB!P11*Assumptions!$B$5
A13: Gross Tax (× tax rate) | B13: 95.8 | C13: 100.7 | D13: 106.1 | E13: 112.7 | F13: 122.2 | G13: =G12*Assumptions!$B$12 | H13: =H12*Assumptions!$B$12 | I13: =I12*Assumptions!$B$12 | J13: =J12*Assumptions!$B$12 | K13: =K12*Assumptions!$B$12 | L13: =L12*Assumptions!$B$12 | M13: =M12*Assumptions!$B$12 | N13: =N12*Assumptions!$B$12 | ... P13: =P12*Assumptions!$B$12
A14: Gamma Benefit (× gamma × tax rate) | B14: 56.1 | C14: 58.9 | D14: 62.1 | E14: 66 | F14: 71.5 | G14: =G12*Assumptions!$B$11*Assumptions!$B$12 | H14: =H12*Assumptions!$B$11*Assumptions!$B$12 | I14: =I12*Assumptions!$B$11*Assumptions!$B$12 | J14: =J12*Assumptions!$B$11*Assumptions!$B$12 | K14: =K12*Assumptions!$B$11*Assumptions!$B$12 | L14: =L12*Assumptions!$B$11*Assumptions!$B$12 | M14: =M12*Assumptions!$B$11*Assumptions!$B$12 | N14: =N12*Assumptions!$B$11*Assumptions!$B$12 | ... P14: =P12*Assumptions!$B$11*Assumptions!$B$12
A15: Net Tax Allowance | B15: 39.7 | C15: 41.8 | D15: 44 | E15: 46.7 | F15: 50.7 | G15: =G13-G14 | H15: =H13-H14 | I15: =I13-I14 | J15: =J13-J14 | K15: =K13-K14 | L15: =L13-L14 | M15: =M13-M14 | N15: =N13-N14 | ... P15: =P13-P14

Sheet Initiatives
A1: STRATEGIC INITIATIVES — Revenue Growth & Cost Reduction Pipeline
A2: $AUD Millions | B2: FY2019A | C2: FY2020A | D2: FY2021A | E2: FY2022A | F2: FY2023A | G2: FY2024E | H2: FY2025E | I2: FY2026E | J2: FY2027E | K2: FY2028E | L2: FY2029E | M2: FY2030E | N2: FY2031E | O2: FY2032E | P2: FY2033E
A4: REVENUE ENHANCEMENT ($M — annual benefit)
A5: Ancillary Services & FCAS Revenue | B5: 0 | C5: 0 | D5: 0 | E5: 0 | F5: 0 | G5: 0 | H5: 3 | I5: 5 | J5: 6 | K5: 7 | L5: 8 | M5: 8 | N5: 8 | O5: 9 | P5: 9
A6: New Connection Pipeline (beyond P004/P007) | B6: 0 | C6: 0 | D6: 0 | E6: 0 | F6: 0 | G6: 0 | H6: 0 | I6: 2 | J6: 3 | K6: 4 | L6: 4 | M6: 5 | N6: 5 | O6: 5 | P6: 6
A7: Tariff Structure & Access Review | B7: 0 | C7: 0 | D7: 0 | E7: 0 | F7: 0 | G7: 0 | H7: 0 | I7: 0 | J7: 4 | K7: 5 | L7: 5 | M7: 5 | N7: 6 | O7: 6 | P7: 6
A8: TOTAL REV INITIATIVES | B8: =B5+B6+B7 | C8: =C5+C6+C7 | D8: =D5+D6+D7 | E8: =E5+E6+E7 | F8: =F5+F6+F7 | G8: =G5+G6+G7 | H8: =H5+H6+H7 | I8: =I5+I6+I7 | ... P8: =P5+P6+P7
A9: → Added to IS Revenue (above base MAR)
A10: OPEX REDUCTION INITIATIVES ($M — annual saving)
A11: Procurement & Supply Chain Savings | B11: 0 | C11: 0 | D11: 0 | E11: 0 | F11: 0 | G11: 0 | H11: 2 | I11: 3 | J11: 4 | K11: 5 | L11: 6 | M11: 6 | N11: 7 | O11: 7 | P11: 7
A12: Digital Automation & Predictive Maintenance | B12: 0 | C12: 0 | D12: 0 | E12: 0 | F12: 0 | G12: 0 | H12: 0 | I12: 1 | J12: 2 | K12: 3 | L12: 3 | M12: 4 | N12: 4 | O12: 5 | P12: 5
A13: Energy Efficiency & Fleet Electrification | B13: 0 | C13: 0 | D13: 0 | E13: 0 | F13: 0 | G13: 0 | H13: 1 | I13: 1 | J13: 2 | K13: 2 | L13: 2 | M13: 2 | N13: 2 | O13: 2 | P13: 2
A14: TOTAL OPEX INITIATIVES | B14: =B11+B12+B13 | C14: =C11+C12+C13 | D14: =D11+D12+D13 | E14: =E11+E12+E13 | F14: =F11+F12+F13 | G14: =G11+G12+G13 | H14: =H11+H12+H13 | I14: =I11+I12+I13 | ... P14: =P11+P12+P13
A15: → Reduces IS Total Opex
A16: FINANCE COST REDUCTION ($M — annual saving)
A17: Debt Refinancing — Lower Benchmark Rate | B17: 0 | C17: 0 | D17: 0 | E17: 0 | F17: 0 | G17: 0 | H17: 4 | I17: 5 | J17: 6 | K17: 7 | L17: 8 | M17: 8 | N17: 9 | O17: 9 | P17: 10
A18: Interest Rate Hedging Programme | B18: 0 | C18: 0 | D18: 0 | E18: 0 | F18: 0 | G18: 0 | H18: 0 | I18: 2 | J18: 2 | K18: 3 | L18: 3 | M18: 3 | N18: 3 | O18: 3 | P18: 3
A19: TOTAL FIN INITIATIVES | B19: =B17+B18 | C19: =C17+C18 | D19: =D17+D18 | E19: =E17+E18 | F19: =F17+F18 | G19: =G17+G18 | H19: =H17+H18 | I19: =I17+I18 | ... P19: =P17+P18
A20: → Reduces IS Interest Expense
A21: DEPRECIATION REDUCTION ($M — annual saving)
A22: Asset Life Extension Review (regulatory approved) | B22: 0 | C22: 0 | D22: 0 | E22: 0 | F22: 0 | G22: 0 | H22: 3 | I22: 4 | J22: 5 | K22: 5 | L22: 5 | M22: 5 | N22: 6 | O22: 6 | P22: 6
A23: Targeted Asset Disposal & Write-Off | B23: 0 | C23: 0 | D23: 0 | E23: 0 | F23: 0 | G23: 0 | H23: 0 | I23: 2 | J23: 2 | K23: 2 | L23: 2 | M23: 2 | N23: 2 | O23: 2 | P23: 2
A24: TOTAL DEP INITIATIVES | B24: =B22+B23 | C24: =C22+C23 | D24: =D22+D23 | E24: =E22+E23 | F24: =F22+F23 | G24: =G22+G23 | H24: =H22+H23 | I24: =I22+I23 | ... P24: =P22+P23
A25: → Reduces IS D&A Charge
A26: NET INITIATIVE VALUE — ANNUAL IMPACT ON NET INCOME ($M)
A27: Net Annual Value (Rev + Opex + Finance + D&A savings, pre-tax) | B27: =B8+B14+B19+B24 | C27: =C8+C14+C19+C24 | D27: =D8+D14+D19+D24 | E27: =E8+E14+E19+E24 | F27: =F8+F14+F19+F24 | G27: =G8+G14+G19+G24 | H27: =H8+H14+H19+H24 | I27: =I8+I14+I19+I24 | ... P27: =P8+P14+P19+P24

Sheet Income Statement
A1: INCOME STATEMENT — Electricity Grid Transmission Utility
A2: $AUD Millions | B2: FY2019A | C2: FY2020A | D2: FY2021A | E2: FY2022A | F2: FY2023A | G2: FY2024E | H2: FY2025E | I2: FY2026E | J2: FY2027E | K2: FY2028E | L2: FY2029E | M2: FY2030E | N2: FY2031E | O2: FY2032E | P2: FY2033E
A4: Revenue ($M)
A5: Transmission Revenue | B5: 597 | C5: 622.5 | D5: 659 | E5: 679.5 | F5: 723 | G5: =PTRM!G9-G6+Initiatives!G8 | H5: =PTRM!H9-H6+Initiatives!H8 | I5: =PTRM!I9-I6+Initiatives!I8 | J5: =PTRM!J9-J6+Initiatives!J8 | K5: =PTRM!K9-K6+Initiatives!K8 | L5: =PTRM!L9-L6+Initiatives!L8 | M5: =PTRM!M9-M6+Initiatives!M8 | N5: =PTRM!N9-N6+Initiatives!N8 | ... P5: =PTRM!P9-P6+Initiatives!P8
A6: Connection & Access Fees | B6: 6 | C6: 6.5 | D6: 7 | E6: 7.5 | F6: 8 | G6: =Assumptions!G20 | H6: =Assumptions!H20 | I6: =Assumptions!I20 | J6: =Assumptions!J20 | K6: =Assumptions!K20 | L6: =Assumptions!L20 | M6: =Assumptions!M20 | N6: =Assumptions!N20 | ... P6: =Assumptions!P20
A7: Total Revenue | B7: 603 | C7: 629 | D7: 666 | E7: 687 | F7: 731 | G7: =PTRM!G9+Initiatives!G8 | H7: =PTRM!H9+Initiatives!H8 | I7: =PTRM!I9+Initiatives!I8 | J7: =PTRM!J9+Initiatives!J8 | K7: =PTRM!K9+Initiatives!K8 | L7: =PTRM!L9+Initiatives!L8 | M7: =PTRM!M9+Initiatives!M8 | N7: =PTRM!N9+Initiatives!N8 | ... P7: =PTRM!P9+Initiatives!P8
A9: Operating Expenditure ($M)
A10: Network O&M | B10: 89 | C10: 92 | D10: 95 | E10: 97 | F10: 100 | G10: =REFM!G5 | H10: =REFM!H5 | I10: =REFM!I5 | J10: =REFM!J5 | K10: =REFM!K5 | L10: =REFM!L5 | M10: =REFM!M5 | N10: =REFM!N5 | ... P10: =REFM!P5
A11: Corporate | B11: 52 | C11: 53 | D11: 54 | E11: 56 | F11: 57 | G11: =REFM!G6 | H11: =REFM!H6 | I11: =REFM!I6 | J11: =REFM!J6 | K11: =REFM!K6 | L11: =REFM!L6 | M11: =REFM!M6 | N11: =REFM!N6 | ... P11: =REFM!P6
A12: Insurance | B12: 18 | C12: 18 | D12: 18 | E12: 19 | F12: 19 | G12: =REFM!G7 | H12: =REFM!H7 | I12: =REFM!I7 | J12: =REFM!J7 | K12: =REFM!K7 | L12: =REFM!L7 | M12: =REFM!M7 | N12: =REFM!N7 | ... P12: =REFM!P7
A13: Regulatory | B13: 9 | C13: 9 | D13: 9 | E13: 9 | F13: 9 | G13: =REFM!G8 | H13: =REFM!H8 | I13: =REFM!I8 | J13: =REFM!J8 | K13: =REFM!K8 | L13: =REFM!L8 | M13: =REFM!M8 | N13: =REFM!N8 | ... P13: =REFM!P8
A14: Total Opex | B14: 168 | C14: 172 | D14: 176 | E14: 181 | F14: 185 | G14: =SUM(G10:G13)-Initiatives!G14 | H14: =SUM(H10:H13)-Initiatives!H14 | I14: =SUM(I10:I13)-Initiatives!I14 | J14: =SUM(J10:J13)-Initiatives!J14 | K14: =SUM(K10:K13)-Initiatives!K14 | L14: =SUM(L10:L13)-Initiatives!L14 | M14: =SUM(M10:M13)-Initiatives!M14 | N14: =SUM(N10:N13)-Initiatives!N14 | ... P14: =SUM(P10:P13)-Initiatives!P14
A16: EBITDA | B16: 435 | C16: 457 | D16: 490 | E16: 506 | F16: 546 | G16: =G7-G14 | H16: =H7-H14 | I16: =I7-I14 | J16: =J7-J14 | K16: =K7-K14 | L16: =L7-L14 | M16: =M7-M14 | N16: =N7-N14 | ... P16: =P7-P14
A18: Depreciation & Amortisation | B18: 230.9 | C18: 239.6 | D18: 249 | E18: 259.1 | F18: 270 | G18: ='Fixed Assets'!G50-Initiatives!G24 | H18: ='Fixed Assets'!H50-Initiatives!H24 | I18: ='Fixed Assets'!I50-Initiatives!I24 | J18: ='Fixed Assets'!J50-Initiatives!J24 | K18: ='Fixed Assets'!K50-Initiatives!K24 | L18: ='Fixed Assets'!L50-Initiatives!L24 | M18: ='Fixed Assets'!M50-Initiatives!M24 | N18: ='Fixed Assets'!N50-Initiatives!N24 | ... P18: ='Fixed Assets'!P50-Initiatives!P24
A20: EBIT | B20: 204.1 | C20: 217.4 | D20: 241 | E20: 246.9 | F20: 276 | G20: =G16-G18 | H20: =H16-H18 | I20: =I16-I18 | J20: =J16-J18 | K20: =K16-K18 | L20: =L16-L18 | M20: =M16-M18 | N20: =N16-N18 | ... P20: =P16-P18
A22: Interest Expense | B22: 192.5 | C22: 195.8 | D22: 199.4 | E22: 203.2 | F22: 207.6 | G22: ='Balance Sheet'!F20*Assumptions!$B$46-Initiatives!G19 | H22: ='Balance Sheet'!G20*Assumptions!$B$46-Initiatives!H19 | I22: ='Balance Sheet'!H20*Assumptions!$B$46-Initiatives!I19 | J22: ='Balance Sheet'!I20*Assumptions!$B$46-Initiatives!J19 | K22: ='Balance Sheet'!J20*Assumptions!$B$46-Initiatives!K19 | L22: ='Balance Sheet'!K20*Assumptions!$B$46-Initiatives!L19 | M22: ='Balance Sheet'!L20*Assumptions!$B$46-Initiatives!M19 | N22: ='Balance Sheet'!M20*Assumptions!$B$46-Initiatives!N19 | ... P22: ='Balance Sheet'!O20*Assumptions!$B$46-Initiatives!P19
A24: EBT | B24: 11.6 | C24: 21.6 | D24: 41.6 | E24: 43.7 | F24: 68.4 | G24: =G20-G22 | H24: =H20-H22 | I24: =I20-I22 | J24: =J20-J22 | K24: =K20-K22 | L24: =L20-L22 | M24: =M20-M22 | N24: =N20-N22 | ... P24: =P20-P22
A26: Income Tax | B26: 3.5 | C26: 6.5 | D26: 12.5 | E26: 13.1 | F26: 20.5 | G26: =MAX(G24*Assumptions!$B$12,0) | H26: =MAX(H24*Assumptions!$B$12,0) | I26: =MAX(I24*Assumptions!$B$12,0) | J26: =MAX(J24*Assumptions!$B$12,0) | K26: =MAX(K24*Assumptions!$B$12,0) | L26: =MAX(L24*Assumptions!$B$12,0) | M26: =MAX(M24*Assumptions!$B$12,0) | N26: =MAX(N24*Assumptions!$B$12,0) | ... P26: =MAX(P24*Assumptions!$B$12,0)
A28: Net Income | B28: 8.1 | C28: 15.1 | D28: 29.1 | E28: 30.6 | F28: 47.9 | G28: =G24-G26 | H28: =H24-H26 | I28: =I24-I26 | J28: =J24-J26 | K28: =K24-K26 | L28: =L24-L26 | M28: =M24-M26 | N28: =N24-N26 | ... P28: =P24-P26
A29: Dividends | B29: 5.7 | C29: 10.6 | D29: 20.4 | E29: 21.4 | F29: 33.5 | G29: =G28*Assumptions!$B$47 | H29: =H28*Assumptions!$B$47 | I29: =I28*Assumptions!$B$47 | J29: =J28*Assumptions!$B$47 | K29: =K28*Assumptions!$B$47 | L29: =L28*Assumptions!$B$47 | M29: =M28*Assumptions!$B$47 | N29: =N28*Assumptions!$B$47 | ... P29: =P28*Assumptions!$B$47
A30: Retained Earnings | B30: 2.4 | C30: 4.5 | D30: 8.7 | E30: 9.2 | F30: 14.4 | G30: =G28-G29 | H30: =H28-H29 | I30: =I28-I29 | J30: =J28-J29 | K30: =K28-K29 | L30: =L28-L29 | M30: =M28-M29 | N30: =N28-N29 | ... P30: =P28-P29

Sheet Balance Sheet
A1: BALANCE SHEET — Electricity Grid Transmission Utility
A2: $AUD Millions | B2: FY2019A | C2: FY2020A | D2: FY2021A | E2: FY2022A | F2: FY2023A | G2: FY2024E | H2: FY2025E | I2: FY2026E | J2: FY2027E | K2: FY2028E | L2: FY2029E | M2: FY2030E | N2: FY2031E | O2: FY2032E | P2: FY2033E
A4: ASSETS ($M)
A5: Cash & Cash Equivalents | B5: 130.3 | C5: 131.5 | D5: 125 | E5: 116.1 | F5: 105.4 | G5: ='Cash Flow'!G24 | H5: ='Cash Flow'!H24 | I5: ='Cash Flow'!I24 | J5: ='Cash Flow'!J24 | K5: ='Cash Flow'!K24 | L5: ='Cash Flow'!L24 | M5: ='Cash Flow'!M24 | N5: ='Cash Flow'!N24 | ... P5: ='Cash Flow'!P24
A6: Accounts Receivable | B6: 74.3 | C6: 77.5 | D6: 82.1 | E6: 84.7 | F6: 90.1 | G6: ='Income Statement'!G7*Assumptions!$B$52/365 | H6: ='Income Statement'!H7*Assumptions!$B$52/365 | I6: ='Income Statement'!I7*Assumptions!$B$52/365 | J6: ='Income Statement'!J7*Assumptions!$B$52/365 | K6: ='Income Statement'!K7*Assumptions!$B$52/365 | L6: ='Income Statement'!L7*Assumptions!$B$52/365 | M6: ='Income Statement'!M7*Assumptions!$B$52/365 | N6: ='Income Statement'!N7*Assumptions!$B$52/365 | ... P6: ='Income Statement'!P7*Assumptions!$B$52/365
A7: Total Current Assets | B7: 204.6 | C7: 209 | D7: 207.1 | E7: 200.8 | F7: 195.5 | G7: =G5+G6 | H7: =H5+H6 | I7: =I5+I6 | J7: =J5+J6 | K7: =K5+K6 | L7: =L5+L6 | M7: =M5+M6 | N7: =N5+N6 | ... P7: =P5+P6
A9: Gross PP&E | B9: 8080 | C9: 8385 | D9: 8715 | E9: 9070 | F9: 9450 | G9: =F9+REFM!G15 | H9: =G9+REFM!H15 | I9: =H9+REFM!I15 | J9: =I9+REFM!J15 | K9: =J9+REFM!K15 | L9: =K9+REFM!L15 | M9: =L9+REFM!M15 | N9: =M9+REFM!N15 | ... P9: =O9+REFM!P15
A10: (Less) Accumulated D&A | B10: 2830.9 | C10: 3070.5 | D10: 3319.5 | E10: 3578.6 | F10: 3848.6 | G10: =F10+'Income Statement'!G18 | H10: =G10+'Income Statement'!H18 | I10: =H10+'Income Statement'!I18 | J10: =I10+'Income Statement'!J18 | K10: =J10+'Income Statement'!K18 | L10: =K10+'Income Statement'!L18 | M10: =L10+'Income Statement'!M18 | N10: =M10+'Income Statement'!N18 | ... P10: =O10+'Income Statement'!P18
A11: Net PP&E | B11: 5249.1 | C11: 5314.5 | D11: 5395.5 | E11: 5491.4 | F11: 5601.4 | G11: =G9-G10 | H11: =H9-H10 | I11: =I9-I10 | J11: =J9-J10 | K11: =K9-K10 | L11: =L9-L10 | M11: =M9-M10 | N11: =N9-N10 | ... P11: =P9-P10
A12: Regulatory Asset (RAB excess over book) | B12: -217.1 | C12: -17.8 | D12: 194.1 | E12: 481.2 | F12: 960.3 | G12: =RAB!G9-G11 | H12: =RAB!H9-H11 | I12: =RAB!I9-I11 | J12: =RAB!J9-J11 | K12: =RAB!K9-K11 | L12: =RAB!L9-L11 | M12: =RAB!M9-M11 | N12: =RAB!N9-N11 | ... P12: =RAB!P9-P11
A13: Total Non-Current Assets | B13: 5032 | C13: 5296.7 | D13: 5589.6 | E13: 5972.6 | F13: 6561.7 | G13: =G11+G12 | H13: =H11+H12 | I13: =I11+I12 | J13: =J11+J12 | K13: =K11+K12 | L13: =L11+L12 | M13: =M11+M12 | N13: =N11+N12 | ... P13: =P11+P12
A14: TOTAL ASSETS | B14: 5236.6 | C14: 5505.7 | D14: 5796.7 | E14: 6173.4 | F14: 6757.2 | G14: =G7+G13 | H14: =H7+H13 | I14: =I7+I13 | J14: =J7+J13 | K14: =K7+K13 | L14: =L7+L13 | M14: =M7+M13 | N14: =N7+N13 | ... P14: =P7+P13
A16: LIABILITIES ($M)
A17: Accounts Payable | B17: 13.8 | C17: 14.1 | D17: 14.5 | E17: 14.9 | F17: 15.2 | G17: =REFM!G9*Assumptions!$B$53/365 | H17: =REFM!H9*Assumptions!$B$53/365 | I17: =REFM!I9*Assumptions!$B$53/365 | J17: =REFM!J9*Assumptions!$B$53/365 | K17: =REFM!K9*Assumptions!$B$53/365 | L17: =REFM!L9*Assumptions!$B$53/365 | M17: =REFM!M9*Assumptions!$B$53/365 | N17: =REFM!N9*Assumptions!$B$53/365 | ... P17: =REFM!P9*Assumptions!$B$53/365
A18: Total Current Liabilities | B18: 13.8 | C18: 14.1 | D18: 14.5 | E18: 14.9 | F18: 15.2 | G18: =G17 | H18: =H17 | I18: =I17 | J18: =J17 | K18: =K17 | L18: =L17 | M18: =M17 | N18: =N17 | ... P18: =P17
A20: Long-Term Debt | B20: 3560 | C20: 3625 | D20: 3695 | E20: 3775 | F20: 3865 | G20: =F20+Assumptions!G48-Assumptions!G49 | H20: =G20+Assumptions!H48-Assumptions!H49 | I20: =H20+Assumptions!I48-Assumptions!I49 | J20: =I20+Assumptions!J48-Assumptions!J49 | K20: =J20+Assumptions!K48-Assumptions!K49 | L20: =K20+Assumptions!L48-Assumptions!L49 | M20: =L20+Assumptions!M48-Assumptions!M49 | N20: =M20+Assumptions!N48-Assumptions!N49 | ... P20: =O20+Assumptions!P48-Assumptions!P49
A21: Deferred Tax Liability | B21: 0 | C21: 0 | D21: 0 | E21: 0 | F21: 0 | G21: =MAX((RAB!G14-G10)*Assumptions!$B$12,0) | H21: =MAX((RAB!H14-H10)*Assumptions!$B$12,0) | I21: =MAX((RAB!I14-I10)*Assumptions!$B$12,0) | J21: =MAX((RAB!J14-J10)*Assumptions!$B$12,0) | K21: =MAX((RAB!K14-K10)*Assumptions!$B$12,0) | L21: =MAX((RAB!L14-L10)*Assumptions!$B$12,0) | M21: =MAX((RAB!M14-M10)*Assumptions!$B$12,0) | N21: =MAX((RAB!N14-N10)*Assumptions!$B$12,0) | ... P21: =MAX((RAB!P14-P10)*Assumptions!$B$12,0)
A22: Total Non-Current Liabilities | B22: 3560 | C22: 3625 | D22: 3695 | E22: 3775 | F22: 3865 | G22: =G20+G21 | H22: =H20+H21 | I22: =I20+I21 | J22: =J20+J21 | K22: =K20+K21 | L22: =L20+L21 | M22: =M20+M21 | N22: =N20+N21 | ... P22: =P20+P21
A23: TOTAL LIABILITIES | B23: 3573.8 | C23: 3639.1 | D23: 3709.5 | E23: 3789.9 | F23: 3880.2 | G23: =G18+G22 | H23: =H18+H22 | I23: =I18+I22 | J23: =J18+J22 | K23: =K18+K22 | L23: =L18+L22 | M23: =M18+M22 | N23: =N18+N22 | ... P23: =P18+P22
A25: EQUITY ($M)
A26: Share Capital & Reserves | B26: 880 | C26: 880 | D26: 880 | E26: 880 | F26: 880 | G26: =F26 | H26: =G26 | I26: =H26 | J26: =I26 | K26: =J26 | L26: =K26 | M26: =L26 | N26: =M26 | ... P26: =O26
A27: Retained Earnings | B27: 422.4 | C27: 426.9 | D27: 435.6 | E27: 444.8 | F27: 459.2 | G27: =F27+'Income Statement'!G30 | H27: =G27+'Income Statement'!H30 | I27: =H27+'Income Statement'!I30 | J27: =I27+'Income Statement'!J30 | K27: =J27+'Income Statement'!K30 | L27: =K27+'Income Statement'!L30 | M27: =L27+'Income Statement'!M30 | N27: =M27+'Income Statement'!N30 | ... P27: =O27+'Income Statement'!P30
A28: Total Equity | B28: 1302.4 | C28: 1306.9 | D28: 1315.6 | E28: 1324.8 | F28: 1339.2 | G28: =G26+G27 | H28: =H26+H27 | I28: =I26+I27 | J28: =J26+J27 | K28: =K26+K27 | L28: =L26+L27 | M28: =M26+M27 | N28: =N26+N27 | ... P28: =P26+P27
A29: TOTAL LIABILITIES & EQUITY | B29: 4876.2 | C29: 4946 | D29: 5025.1 | E29: 5114.7 | F29: 5219.4 | G29: =G23+G28 | H29: =H23+H28 | I29: =I23+I28 | J29: =J23+J28 | K29: =K23+K28 | L29: =L23+L28 | M29: =M23+M28 | N29: =N23+N28 | ... P29: =P23+P28

Sheet Cash Flow
A1: CASH FLOW STATEMENT — Indirect Method
A2: $AUD Millions | B2: FY2019A | C2: FY2020A | D2: FY2021A | E2: FY2022A | F2: FY2023A | G2: FY2024E | H2: FY2025E | I2: FY2026E | J2: FY2027E | K2: FY2028E | L2: FY2029E | M2: FY2030E | N2: FY2031E | O2: FY2032E | P2: FY2033E
A4: OPERATING ACTIVITIES ($M)
A5: Net Income | B5: 8.1 | C5: 15.1 | D5: 29.1 | E5: 30.6 | F5: 47.9 | G5: ='Income Statement'!G28 | H5: ='Income Statement'!H28 | I5: ='Income Statement'!I28 | J5: ='Income Statement'!J28 | K5: ='Income Statement'!K28 | L5: ='Income Statement'!L28 | M5: ='Income Statement'!M28 | N5: ='Income Statement'!N28 | ... P5: ='Income Statement'!P28
A6: + Depreciation & Amortisation | B6: 230.9 | C6: 239.6 | D6: 249 | E6: 259.1 | F6: 270 | G6: ='Income Statement'!G18 | H6: ='Income Statement'!H18 | I6: ='Income Statement'!I18 | J6: ='Income Statement'!J18 | K6: ='Income Statement'!K18 | L6: ='Income Statement'!L18 | M6: ='Income Statement'!M18 | N6: ='Income Statement'!N18 | ... P6: ='Income Statement'!P18
A7: +/− Change in Accounts Receivable | B7: -3.7 | C7: -3.2 | D7: -4.6 | E7: -2.6 | F7: -5.4 | G7: =-('Balance Sheet'!G6-'Balance Sheet'!F6) | H7: =-('Balance Sheet'!H6-'Balance Sheet'!G6) | I7: =-('Balance Sheet'!I6-'Balance Sheet'!H6) | J7: =-('Balance Sheet'!J6-'Balance Sheet'!I6) | K7: =-('Balance Sheet'!K6-'Balance Sheet'!J6) | L7: =-('Balance Sheet'!L6-'Balance Sheet'!K6) | M7: =-('Balance Sheet'!M6-'Balance Sheet'!L6) | N7: =-('Balance Sheet'!N6-'Balance Sheet'!M6) | ... P7: =-('Balance Sheet'!P6-'Balance Sheet'!O6)
A8: +/− Change in Accounts Payable | B8: 0.7 | C8: 0.3 | D8: 0.4 | E8: 0.4 | F8: 0.3 | G8: ='Balance Sheet'!G17-'Balance Sheet'!F17 | H8: ='Balance Sheet'!H17-'Balance Sheet'!G17 | I8: ='Balance Sheet'!I17-'Balance Sheet'!H17 | J8: ='Balance Sheet'!J17-'Balance Sheet'!I17 | K8: ='Balance Sheet'!K17-'Balance Sheet'!J17 | L8: ='Balance Sheet'!L17-'Balance Sheet'!K17 | M8: ='Balance Sheet'!M17-'Balance Sheet'!L17 | N8: ='Balance Sheet'!N17-'Balance Sheet'!M17 | ... P8: ='Balance Sheet'!P17-'Balance Sheet'!O17
A9: +/− Change in Regulatory Assets | B9: 0 | C9: 0 | D9: 0 | E9: 0 | F9: 0 | G9: =-('Balance Sheet'!G12-'Balance Sheet'!F12) | H9: =-('Balance Sheet'!H12-'Balance Sheet'!G12) | I9: =-('Balance Sheet'!I12-'Balance Sheet'!H12) | J9: =-('Balance Sheet'!J12-'Balance Sheet'!I12) | K9: =-('Balance Sheet'!K12-'Balance Sheet'!J12) | L9: =-('Balance Sheet'!L12-'Balance Sheet'!K12) | M9: =-('Balance Sheet'!M12-'Balance Sheet'!L12) | N9: =-('Balance Sheet'!N12-'Balance Sheet'!M12) | ... P9: =-('Balance Sheet'!P12-'Balance Sheet'!O12)
A10: Net Cash from Operating Activities | B10: 236 | C10: 251.8 | D10: 273.9 | E10: 287.5 | F10: 312.8 | G10: =SUM(G5:G9) | H10: =SUM(H5:H9) | I10: =SUM(I5:I9) | J10: =SUM(J5:J9) | K10: =SUM(K5:K9) | L10: =SUM(L5:L9) | M10: =SUM(M5:M9) | N10: =SUM(N5:N9) | ... P10: =SUM(P5:P9)
A12: INVESTING ACTIVITIES ($M)
A13: Capital Expenditure | B13: -280 | C13: -305 | D13: -330 | E13: -355 | F13: -380 | G13: =-REFM!G15 | H13: =-REFM!H15 | I13: =-REFM!I15 | J13: =-REFM!J15 | K13: =-REFM!K15 | L13: =-REFM!L15 | M13: =-REFM!M15 | N13: =-REFM!N15 | ... P13: =-REFM!P15
A14: Net Cash from Investing Activities | B14: -280 | C14: -305 | D14: -330 | E14: -355 | F14: -380 | G14: =G13 | H14: =H13 | I14: =I13 | J14: =J13 | K14: =K13 | L14: =L13 | M14: =M13 | N14: =N13 | ... P14: =P13
A16: FINANCING ACTIVITIES ($M)
A17: Debt Issuances | B17: 300 | C17: 310 | D17: 320 | E17: 340 | F17: 360 | G17: =Assumptions!G48 | H17: =Assumptions!H48 | I17: =Assumptions!I48 | J17: =Assumptions!J48 | K17: =Assumptions!K48 | L17: =Assumptions!L48 | M17: =Assumptions!M48 | N17: =Assumptions!N48 | ... P17: =Assumptions!P48
A18: Debt Repayments | B18: -240 | C18: -245 | D18: -250 | E18: -260 | F18: -270 | G18: =-Assumptions!G49 | H18: =-Assumptions!H49 | I18: =-Assumptions!I49 | J18: =-Assumptions!J49 | K18: =-Assumptions!K49 | L18: =-Assumptions!L49 | M18: =-Assumptions!M49 | N18: =-Assumptions!N49 | ... P18: =-Assumptions!P49
A19: Dividends Paid | B19: -5.7 | C19: -10.6 | D19: -20.4 | E19: -21.4 | F19: -33.5 | G19: =-'Income Statement'!G29 | H19: =-'Income Statement'!H29 | I19: =-'Income Statement'!I29 | J19: =-'Income Statement'!J29 | K19: =-'Income Statement'!K29 | L19: =-'Income Statement'!L29 | M19: =-'Income Statement'!M29 | N19: =-'Income Statement'!N29 | ... P19: =-'Income Statement'!P29
